<?xml version="1.0" ?>
<!-- =================================================================================== -->
<!-- |    This document was autogenerated by xacro from src/eli_cs_robot_description/urdf/cs.urdf.xacro | -->
<!-- |    EDITING THIS FILE BY HAND IS NOT RECOMMENDED                                 | -->
<!-- =================================================================================== -->
<robot name="cs625">
  <!--
    Base ELITE CS robot series xacro macro.

    NOTE this is NOT a URDF. It cannot directly be loaded by consumers
    expecting a flattened '.urdf' file. See the top-level '.xacro' for that
    (but note that .xacro must still be processed by the xacro command).

    This file models the base kinematic chain of a CS robot, which then gets
    parameterised by various configuration files to convert it into a CS63,
    CS66, CS612, CS616, CS620 or CS625.

    NOTE the default kinematic parameters (i.e., link lengths, frame locations,
    offsets, etc) do not correspond to any particular robot. They are defaults
    only. 

    For accurate (and robot-specific) transforms, the 'kinematics_parameters_file'
    parameter MUST point to a .yaml file containing the appropriate values for
    the targeted robot.

     - Chen Shichao
  -->
  <!--
    NOTE the macro defined in this file is NOT part of the public API of this
          package. Users CANNOT rely on this file being available, or stored in
          this location. Nor can they rely on the existence of the macro.
  -->
  <!-- create link fixed to the "world" -->
  <link name="world"/>
  <ros2_control name="cs625" type="system">
    <hardware>
      <plugin>ELITE_CS_ROBOT_ROS_DRIVER/EliteCSPositionHardwareInterface</plugin>
      <param name="robot_ip">0.0.0.0</param>
      <param name="script_filename"></param>
      <param name="output_recipe_filename"></param>
      <param name="input_recipe_filename"></param>
      <param name="headless_mode">False</param>
      <param name="reverse_port">50001</param>
      <param name="script_sender_port">50002</param>
      <param name="local_ip">0.0.0.0</param>
      <param name="script_command_port">50004</param>
      <param name="trajectory_port">50003</param>
      <param name="tf_prefix"></param>
      <param name="servoj_gain">1000</param>
      <param name="servoj_lookahead_time">0.03</param>
      <param name="servoj_time">0.008</param>
      <param name="use_tool_communication">False</param>
      <param name="tool_voltage">0</param>
      <param name="tool_parity">0</param>
      <param name="tool_baud_rate">115200</param>
      <param name="tool_stop_bits">1</param>
      <param name="tool_tcp_port">54321</param>
      <param name="robot_receive_timeout">0</param>
    </hardware>
    <joint name="shoulder_pan_joint">
      <command_interface name="position"/>
      <command_interface name="velocity"/>
      <state_interface name="position">
        <!-- initial position for the FakeSystem and simulation -->
        <param name="initial_value">0.0</param>
      </state_interface>
      <state_interface name="velocity"/>
      <state_interface name="effort"/>
    </joint>
    <joint name="shoulder_lift_joint">
      <command_interface name="position"/>
      <command_interface name="velocity"/>
      <state_interface name="position">
        <!-- initial position for the FakeSystem and simulation -->
        <param name="initial_value">-1.57</param>
      </state_interface>
      <state_interface name="velocity"/>
      <state_interface name="effort"/>
    </joint>
    <joint name="elbow_joint">
      <command_interface name="position"/>
      <command_interface name="velocity"/>
      <state_interface name="position">
        <!-- initial position for the FakeSystem and simulation -->
        <param name="initial_value">0.0</param>
      </state_interface>
      <state_interface name="velocity"/>
      <state_interface name="effort"/>
    </joint>
    <joint name="wrist_1_joint">
      <command_interface name="position"/>
      <command_interface name="velocity"/>
      <state_interface name="position">
        <!-- initial position for the FakeSystem and simulation -->
        <param name="initial_value">-1.57</param>
      </state_interface>
      <state_interface name="velocity"/>
      <state_interface name="effort"/>
    </joint>
    <joint name="wrist_2_joint">
      <command_interface name="position"/>
      <command_interface name="velocity"/>
      <state_interface name="position">
        <!-- initial position for the FakeSystem and simulation -->
        <param name="initial_value">1.57</param>
      </state_interface>
      <state_interface name="velocity"/>
      <state_interface name="effort"/>
    </joint>
    <joint name="wrist_3_joint">
      <command_interface name="position"/>
      <command_interface name="velocity"/>
      <state_interface name="position">
        <!-- initial position for the FakeSystem and simulation -->
        <param name="initial_value">0.0</param>
      </state_interface>
      <state_interface name="velocity"/>
      <state_interface name="effort"/>
    </joint>
    <sensor name="tcp_fts_sensor">
      <state_interface name="force.x"/>
      <state_interface name="force.y"/>
      <state_interface name="force.z"/>
      <state_interface name="torque.x"/>
      <state_interface name="torque.y"/>
      <state_interface name="torque.z"/>
    </sensor>
    <sensor name="tcp_pose">
      <state_interface name="position.x"/>
      <state_interface name="position.y"/>
      <state_interface name="position.z"/>
      <state_interface name="orientation.x"/>
      <state_interface name="orientation.y"/>
      <state_interface name="orientation.z"/>
      <state_interface name="orientation.w"/>
    </sensor>
    <!-- NOTE The following are joints used only for testing with fake hardware and will change in the future -->
    <gpio name="speed_scaling">
      <state_interface name="speed_scaling_factor"/>
      <param name="initial_speed_scaling_factor">1</param>
      <command_interface name="target_speed_fraction_cmd"/>
      <command_interface name="target_speed_fraction_async_success"/>
    </gpio>
    <gpio name="gpio">
      <command_interface name="standard_digital_output_cmd_0"/>
      <command_interface name="standard_digital_output_cmd_1"/>
      <command_interface name="standard_digital_output_cmd_2"/>
      <command_interface name="standard_digital_output_cmd_3"/>
      <command_interface name="standard_digital_output_cmd_4"/>
      <command_interface name="standard_digital_output_cmd_5"/>
      <command_interface name="standard_digital_output_cmd_6"/>
      <command_interface name="standard_digital_output_cmd_7"/>
      <command_interface name="standard_digital_output_cmd_8"/>
      <command_interface name="standard_digital_output_cmd_9"/>
      <command_interface name="standard_digital_output_cmd_10"/>
      <command_interface name="standard_digital_output_cmd_11"/>
      <command_interface name="standard_digital_output_cmd_12"/>
      <command_interface name="standard_digital_output_cmd_13"/>
      <command_interface name="standard_digital_output_cmd_14"/>
      <command_interface name="standard_digital_output_cmd_15"/>
      <command_interface name="configure_digital_output_cmd_0"/>
      <command_interface name="configure_digital_output_cmd_1"/>
      <command_interface name="configure_digital_output_cmd_2"/>
      <command_interface name="configure_digital_output_cmd_3"/>
      <command_interface name="configure_digital_output_cmd_4"/>
      <command_interface name="configure_digital_output_cmd_5"/>
      <command_interface name="configure_digital_output_cmd_6"/>
      <command_interface name="configure_digital_output_cmd_7"/>
      <command_interface name="tool_digital_output_cmd_0"/>
      <command_interface name="tool_digital_output_cmd_1"/>
      <command_interface name="tool_digital_output_cmd_2"/>
      <command_interface name="tool_digital_output_cmd_3"/>
      <command_interface name="standard_analog_output_type_cmd_0"/>
      <command_interface name="standard_analog_output_type_cmd_1"/>
      <command_interface name="standard_analog_output_cmd_0"/>
      <command_interface name="standard_analog_output_cmd_1"/>
      <command_interface name="tool_voltage_cmd"/>
      <command_interface name="io_async_success"/>
      <state_interface name="standard_digital_output_0"/>
      <state_interface name="standard_digital_output_1"/>
      <state_interface name="standard_digital_output_2"/>
      <state_interface name="standard_digital_output_3"/>
      <state_interface name="standard_digital_output_4"/>
      <state_interface name="standard_digital_output_5"/>
      <state_interface name="standard_digital_output_6"/>
      <state_interface name="standard_digital_output_7"/>
      <state_interface name="standard_digital_output_8"/>
      <state_interface name="standard_digital_output_9"/>
      <state_interface name="standard_digital_output_10"/>
      <state_interface name="standard_digital_output_11"/>
      <state_interface name="standard_digital_output_12"/>
      <state_interface name="standard_digital_output_13"/>
      <state_interface name="standard_digital_output_14"/>
      <state_interface name="standard_digital_output_15"/>
      <state_interface name="configure_digital_output_0"/>
      <state_interface name="configure_digital_output_1"/>
      <state_interface name="configure_digital_output_2"/>
      <state_interface name="configure_digital_output_3"/>
      <state_interface name="configure_digital_output_4"/>
      <state_interface name="configure_digital_output_5"/>
      <state_interface name="configure_digital_output_6"/>
      <state_interface name="configure_digital_output_7"/>
      <state_interface name="tool_digital_output_0"/>
      <state_interface name="tool_digital_output_1"/>
      <state_interface name="tool_digital_output_2"/>
      <state_interface name="tool_digital_output_3"/>
      <state_interface name="standard_digital_input_0"/>
      <state_interface name="standard_digital_input_1"/>
      <state_interface name="standard_digital_input_2"/>
      <state_interface name="standard_digital_input_3"/>
      <state_interface name="standard_digital_input_4"/>
      <state_interface name="standard_digital_input_5"/>
      <state_interface name="standard_digital_input_6"/>
      <state_interface name="standard_digital_input_7"/>
      <state_interface name="standard_digital_input_8"/>
      <state_interface name="standard_digital_input_9"/>
      <state_interface name="standard_digital_input_10"/>
      <state_interface name="standard_digital_input_11"/>
      <state_interface name="standard_digital_input_12"/>
      <state_interface name="standard_digital_input_13"/>
      <state_interface name="standard_digital_input_14"/>
      <state_interface name="standard_digital_input_15"/>
      <state_interface name="configure_digital_input_0"/>
      <state_interface name="configure_digital_input_1"/>
      <state_interface name="configure_digital_input_2"/>
      <state_interface name="configure_digital_input_3"/>
      <state_interface name="configure_digital_input_4"/>
      <state_interface name="configure_digital_input_5"/>
      <state_interface name="configure_digital_input_6"/>
      <state_interface name="configure_digital_input_7"/>
      <state_interface name="tool_digital_input_0"/>
      <state_interface name="tool_digital_input_1"/>
      <state_interface name="tool_digital_input_2"/>
      <state_interface name="tool_digital_input_3"/>
      <state_interface name="standard_analog_output_type_0"/>
      <state_interface name="standard_analog_output_type_1"/>
      <state_interface name="standard_analog_output_0"/>
      <state_interface name="standard_analog_output_1"/>
      <state_interface name="standard_analog_input_type_0"/>
      <state_interface name="standard_analog_input_type_1"/>
      <state_interface name="standard_analog_input_0"/>
      <state_interface name="standard_analog_input_1"/>
      <state_interface name="tool_mode"/>
      <state_interface name="tool_output_voltage"/>
      <state_interface name="tool_output_current"/>
      <state_interface name="tool_temperature"/>
      <state_interface name="tool_analog_input"/>
      <state_interface name="tool_analog_output"/>
      <state_interface name="tool_analog_input_type"/>
      <state_interface name="tool_analog_output_type"/>
      <state_interface name="robot_mode"/>
      <state_interface name="robot_status_bit_0"/>
      <state_interface name="robot_status_bit_1"/>
      <state_interface name="robot_status_bit_2"/>
      <state_interface name="robot_status_bit_3"/>
      <state_interface name="safety_mode"/>
      <state_interface name="safety_status_bit_0"/>
      <state_interface name="safety_status_bit_1"/>
      <state_interface name="safety_status_bit_2"/>
      <state_interface name="safety_status_bit_3"/>
      <state_interface name="safety_status_bit_4"/>
      <state_interface name="safety_status_bit_5"/>
      <state_interface name="safety_status_bit_6"/>
      <state_interface name="safety_status_bit_7"/>
      <state_interface name="safety_status_bit_8"/>
      <state_interface name="safety_status_bit_9"/>
      <state_interface name="safety_status_bit_10"/>
      <state_interface name="task_running"/>
    </gpio>
    <gpio name="payload">
      <command_interface name="mass"/>
      <command_interface name="cog.x"/>
      <command_interface name="cog.y"/>
      <command_interface name="cog.z"/>
      <command_interface name="payload_async_success"/>
    </gpio>
    <gpio name="resend_external_script">
      <command_interface name="resend_external_script_cmd"/>
      <command_interface name="resend_external_script_async_success"/>
    </gpio>
    <gpio name="hand_back_control">
      <command_interface name="hand_back_control_cmd"/>
      <command_interface name="hand_back_control_async_success"/>
    </gpio>
    <gpio name="zero_ftsensor">
      <command_interface name="zero_ftsensor_cmd"/>
      <command_interface name="zero_ftsensor_async_success"/>
    </gpio>
    <gpio name="freedrive_mode">
      <command_interface name="freedrive_async_success"/>
      <command_interface name="freedrive_start_cmd"/>
      <command_interface name="freedrive_end_cmd"/>
    </gpio>
    <gpio name="system_interface">
      <state_interface name="initialized"/>
    </gpio>
  </ros2_control>
  <!-- Add URDF transmission elements (for ros_control) -->
  <!--<xacro:cs_arm_transmission prefix="${prefix}" hw_interface="${transmission_hw_interface}" />-->
  <!-- Placeholder for ros2_control transmission which don't yet exist -->
  <!-- links -  main serial chain -->
  <link name="base_link"/>
  <link name="base_link_inertia">
    <visual>
      <origin rpy="0 0 0" xyz="0 0 0"/>
      <geometry>
        <mesh filename="package://eli_cs_robot_description/meshes/cs625/visual/base.dae"/>
      </geometry>
    </visual>
    <collision>
      <origin rpy="0 0 0" xyz="0 0 0"/>
      <geometry>
        <mesh filename="package://eli_cs_robot_description/meshes/cs625/collision/base.stl"/>
      </geometry>
    </collision>
    <inertial>
      <mass value="1.50561968754018"/>
      <origin rpy="0 0 0" xyz="-2.4008693014781e-05 0.00117748953656619 0.0762927770474629"/>
      <inertia ixx="0.00678289120631133" ixy="2.67618063769984e-07" ixz="-2.56895564177072e-06" iyy="0.00685230321535615" iyz="9.42628790478668e-05" izz="0.0100437671447022"/>
    </inertial>
  </link>
  <link name="shoulder_link">
    <visual>
      <origin rpy="0 0 0" xyz="0 0 0"/>
      <geometry>
        <mesh filename="package://eli_cs_robot_description/meshes/cs625/visual/shoulder.dae"/>
      </geometry>
    </visual>
    <collision>
      <origin rpy="0 0 0" xyz="0 0 0"/>
      <geometry>
        <mesh filename="package://eli_cs_robot_description/meshes/cs625/collision/shoulder.stl"/>
      </geometry>
    </collision>
    <inertial>
      <mass value="17.04"/>
      <origin rpy="0 0 0" xyz="9.9e-05 -0.026311 -0.026723"/>
      <inertia ixx="0.13029" ixy="-8.271e-05" ixz="0.0001067" iyy="0.085215" iyz="-0.00066335" izz="0.11386"/>
    </inertial>
  </link>
  <link name="upperarm_link">
    <visual>
      <origin rpy="0 0 0" xyz="0 0 0"/>
      <geometry>
        <mesh filename="package://eli_cs_robot_description/meshes/cs625/visual/upperarm.dae"/>
      </geometry>
    </visual>
    <collision>
      <origin rpy="0 0 0" xyz="0 0 0"/>
      <geometry>
        <mesh filename="package://eli_cs_robot_description/meshes/cs625/collision/upperarm.stl"/>
      </geometry>
    </collision>
    <inertial>
      <mass value="26.543"/>
      <origin rpy="0 0 0" xyz="-0.27762 -1.7e-05 0.20184"/>
      <inertia ixx="1.197" ixy="-0.00083272" ixz="-1.5396" iyy="6.1117" iyz="-0.00015496" izz="5.022"/>
    </inertial>
  </link>
  <link name="forearm_link">
    <visual>
      <origin rpy="0 0 0" xyz="0 0 0"/>
      <geometry>
        <mesh filename="package://eli_cs_robot_description/meshes/cs625/visual/forearm.dae"/>
      </geometry>
    </visual>
    <collision>
      <origin rpy="0 0 0" xyz="0 0 0"/>
      <geometry>
        <mesh filename="package://eli_cs_robot_description/meshes/cs625/collision/forearm.stl"/>
      </geometry>
    </collision>
    <inertial>
      <mass value="7.816"/>
      <origin rpy="0 0 0" xyz="-0.30259 2.1e-05 0.07237"/>
      <inertia ixx="0.067797" ixy="4.4997e-05" ixz="-0.12636" iyy="1.3409" iyz="1.45e-05" izz="1.2908"/>
    </inertial>
  </link>
  <link name="wrist_1_link">
    <visual>
      <origin rpy="0 0 0" xyz="0 0 0"/>
      <geometry>
        <mesh filename="package://eli_cs_robot_description/meshes/cs625/visual/wrist1.dae"/>
      </geometry>
    </visual>
    <collision>
      <origin rpy="0 0 0" xyz="0 0 0"/>
      <geometry>
        <mesh filename="package://eli_cs_robot_description/meshes/cs625/collision/wrist1.stl"/>
      </geometry>
    </collision>
    <inertial>
      <mass value="3.095"/>
      <origin rpy="0 0 0" xyz="-3.7e-05 -0.01051 -0.014865"/>
      <inertia ixx="0.0079584" ixy="-3.024e-06" ixz="5.734e-06" iyy="0.0066863" iyz="1.766e-05" izz="0.0048407"/>
    </inertial>
  </link>
  <link name="wrist_2_link">
    <visual>
      <origin rpy="0 0 0" xyz="0 0 0"/>
      <geometry>
        <mesh filename="package://eli_cs_robot_description/meshes/cs625/visual/wrist2.dae"/>
      </geometry>
    </visual>
    <collision>
      <origin rpy="0 0 0" xyz="0 0 0"/>
      <geometry>
        <mesh filename="package://eli_cs_robot_description/meshes/cs625/collision/wrist2.stl"/>
      </geometry>
    </collision>
    <inertial>
      <mass value="3.095"/>
      <origin rpy="0 0 0" xyz="3.7e-05 0.01051 -0.014865"/>
      <inertia ixx="0.007958413" ixy="-3.024e-06" ixz="5.734e-06" iyy="0.006686348" iyz="1.766e-05" izz="0.004840671"/>
    </inertial>
  </link>
  <link name="wrist_3_link">
    <visual>
      <origin rpy="0 0 0" xyz="0 0 0"/>
      <geometry>
        <mesh filename="package://eli_cs_robot_description/meshes/cs625/visual/wrist3.dae"/>
      </geometry>
    </visual>
    <collision>
      <origin rpy="0 0 0" xyz="0 0 0"/>
      <geometry>
        <mesh filename="package://eli_cs_robot_description/meshes/cs625/collision/wrist3.stl"/>
      </geometry>
    </collision>
    <inertial>
      <mass value="0.879"/>
      <origin rpy="0 0 0" xyz="0.000242 -0.001192 -0.050422"/>
      <inertia ixx="0.004065851" ixy="1.5185e-05" ixz="-1.1453e-05" iyy="0.004060372" iyz="4.2152e-05" izz="0.001170392"/>
    </inertial>
  </link>
  <!-- base_joint fixes base_link to the environment -->
  <joint name="base_joint" type="fixed">
    <origin rpy="0 0 0" xyz="0 0 0"/>
    <parent link="world"/>
    <child link="base_link"/>
  </joint>
  <!-- joints - main serial chain -->
  <joint name="base_link-base_link_inertia" type="fixed">
    <parent link="base_link"/>
    <child link="base_link_inertia"/>
    <origin rpy="0 0 0" xyz="0 0 0"/>
  </joint>
  <joint name="shoulder_pan_joint" type="revolute">
    <parent link="base_link_inertia"/>
    <child link="shoulder_link"/>
    <origin rpy="0 0 0" xyz="0 0 0.227828"/>
    <axis xyz="0 0 1"/>
    <limit effort="730.0" lower="-6.283185307179586" upper="6.283185307179586" velocity="2.0943951023931953"/>
    <dynamics damping="0" friction="0"/>
  </joint>
  <joint name="shoulder_lift_joint" type="revolute">
    <parent link="shoulder_link"/>
    <child link="upperarm_link"/>
    <origin rpy="1.570796326589793 0 0" xyz="0 0 0"/>
    <axis xyz="0 0 1"/>
    <limit effort="730.0" lower="-6.283185307179586" upper="6.283185307179586" velocity="2.0943951023931953"/>
    <dynamics damping="0" friction="0"/>
  </joint>
  <joint name="elbow_joint" type="revolute">
    <parent link="upperarm_link"/>
    <child link="forearm_link"/>
    <origin rpy="0 0 0" xyz="-0.749559 0 0"/>
    <axis xyz="0 0 1"/>
    <limit effort="430.0" lower="-3.141592653589793" upper="3.141592653589793" velocity="2.6179938779914944"/>
    <dynamics damping="0" friction="0"/>
  </joint>
  <joint name="wrist_1_joint" type="revolute">
    <parent link="forearm_link"/>
    <child link="wrist_1_link"/>
    <origin rpy="0 0 0" xyz="-0.624488 0 0.173237"/>
    <axis xyz="0 0 1"/>
    <limit effort="100.0" lower="-6.283185307179586" upper="6.283185307179586" velocity="3.6651914291880923"/>
    <dynamics damping="0" friction="0"/>
  </joint>
  <joint name="wrist_2_joint" type="revolute">
    <parent link="wrist_1_link"/>
    <child link="wrist_2_link"/>
    <origin rpy="1.570796326589793 0 0" xyz="0 -0.128407 0"/>
    <axis xyz="0 0 1"/>
    <limit effort="100.0" lower="-6.283185307179586" upper="6.283185307179586" velocity="3.6651914291880923"/>
    <dynamics damping="0" friction="0"/>
  </joint>
  <joint name="wrist_3_joint" type="revolute">
    <parent link="wrist_2_link"/>
    <child link="wrist_3_link"/>
    <origin rpy="-1.570796326589793 0 0" xyz="0 0.128152 0"/>
    <axis xyz="0 0 1"/>
    <limit effort="100.0" lower="-6.283185307179586" upper="6.283185307179586" velocity="3.6651914291880923"/>
    <dynamics damping="0" friction="0"/>
  </joint>
  <link name="ft_frame"/>
  <joint name="wrist_3_link-ft_frame" type="fixed">
    <parent link="wrist_3_link"/>
    <child link="ft_frame"/>
    <origin rpy="0 0 0" xyz="0 0 0"/>
  </joint>
  <!-- ROS-Industrial 'base' frame - base_link to CS 'Base' Coordinates transform -->
  <link name="base"/>
  <joint name="base_link-base_fixed_joint" type="fixed">
    <origin rpy="0 0 0" xyz="0 0 0"/>
    <parent link="base_link"/>
    <child link="base"/>
  </joint>
  <!-- ROS-Industrial 'flange' frame - attachment point for EEF models -->
  <link name="flange"/>
  <joint name="wrist_3-flange" type="fixed">
    <parent link="wrist_3_link"/>
    <child link="flange"/>
    <origin rpy="0 0 0" xyz="0 0 0"/>
  </joint>
  <!-- ================================================================= -->
  <!-- ==============  定义并连接你的末端执行器 (EEF) ============== -->
  <!-- ================================================================= -->
  <link name="my_end_effector_link">
    <visual>
      <origin rpy="0 0 0" xyz="0 0 0"/>
      <geometry>
        <!-- 修正：将毫米单位的STL转换为米 -->
        <mesh filename="package://eli_cs_robot_description/meshes/visual/tool0_vision.STL" scale="0.001 0.001 0.001"/>
      </geometry>
      <material name="eef_color">
        <!-- 修改为银色 (明亮的灰色) -->
        <color rgba="0.75 0.75 0.75 1.0"/>
      </material>
    </visual>
    <collision>
      <origin rpy="0 0 0" xyz="0 0 0"/>
      <geometry>
        <!-- 碰撞模型也同样缩放 -->
        <mesh filename="package://eli_cs_robot_description/meshes/visual/tool0_collision.STL" scale="0.001 0.001 0.001"/>
      </geometry>
    </collision>
  </link>
  <joint name="flange_to_eef_joint" type="fixed">
    <parent link="flange"/>
    <child link="my_end_effector_link"/>
    <origin rpy="0 0 0" xyz="-0.046 0 0.353"/>
  </joint>
</robot>
